2017-06-19 19:51:38,094 - ERROR - Exception TypeError: cannot instantiate ctype 'EVP_MD_CTX' of unknown size
	['  File "init_spreadsheet.py", line 18, in <module>\n    spread = SheetsDecorator(load_spreadsheet=False, credentials=credentials_path)\n', '  File "/Users/austinshih/Desktop/Chomppa/beer_pong_bot-master/chomps/sheetsdecorator.py", line 24, in __init__\n    self._init_pygsheets()\n', '  File "/Users/austinshih/Desktop/Chomppa/beer_pong_bot-master/chomps/sheetsdecorator.py", line 46, in _init_pygsheets\n    self.gc = pygsheets.authorize(service_file=self.credentials)\n', '  File "//anaconda/lib/python3.5/site-packages/pygsheets/client.py", line 515, in authorize\n    rclient = Client(oauth=credentials, **client_kwargs)\n', '  File "//anaconda/lib/python3.5/site-packages/pygsheets/client.py", line 72, in __init__\n    self._fetch_sheets()\n', '  File "//anaconda/lib/python3.5/site-packages/pygsheets/client.py", line 83, in _fetch_sheets\n    results = self._execute_request(None, request, False)\n', '  File "//anaconda/lib/python3.5/site-packages/pygsheets/client.py", line 381, in _execute_request\n    response = request.execute()\n', '  File "//anaconda/lib/python3.5/site-packages/oauth2client/_helpers.py", line 133, in positional_wrapper\n    return wrapped(*args, **kwargs)\n', '  File "//anaconda/lib/python3.5/site-packages/googleapiclient/http.py", line 835, in execute\n    method=str(self.method), body=self.body, headers=self.headers)\n', '  File "//anaconda/lib/python3.5/site-packages/googleapiclient/http.py", line 162, in _retry_request\n    resp, content = http.request(uri, method, *args, **kwargs)\n', '  File "//anaconda/lib/python3.5/site-packages/oauth2client/transport.py", line 159, in new_request\n    credentials._refresh(orig_request_method)\n', '  File "//anaconda/lib/python3.5/site-packages/oauth2client/client.py", line 749, in _refresh\n    self._do_refresh_request(http)\n', '  File "//anaconda/lib/python3.5/site-packages/oauth2client/client.py", line 774, in _do_refresh_request\n    body = self._generate_refresh_request_body()\n', '  File "//anaconda/lib/python3.5/site-packages/oauth2client/client.py", line 1484, in _generate_refresh_request_body\n    assertion = self._generate_assertion()\n', '  File "//anaconda/lib/python3.5/site-packages/oauth2client/service_account.py", line 385, in _generate_assertion\n    key_id=self._private_key_id)\n', '  File "//anaconda/lib/python3.5/site-packages/oauth2client/crypt.py", line 97, in make_signed_jwt\n    signature = signer.sign(signing_input)\n', '  File "//anaconda/lib/python3.5/site-packages/oauth2client/_openssl_crypt.py", line 97, in sign\n    return crypto.sign(self._key, message, \'sha256\')\n', '  File "//anaconda/lib/python3.5/site-packages/OpenSSL/crypto.py", line 2563, in sign\n    md_ctx = _ffi.new("EVP_MD_CTX*")\n']
2017-06-19 19:53:32,155 - ERROR - Exception TypeError: cannot instantiate ctype 'EVP_MD_CTX' of unknown size
	['  File "init_spreadsheet.py", line 18, in <module>\n    spread = SheetsDecorator(load_spreadsheet=False, credentials=credentials_path)\n', '  File "/Users/austinshih/Desktop/Chomppa/beer_pong_bot-master/chomps/sheetsdecorator.py", line 24, in __init__\n    self._init_pygsheets()\n', '  File "/Users/austinshih/Desktop/Chomppa/beer_pong_bot-master/chomps/sheetsdecorator.py", line 46, in _init_pygsheets\n    self.gc = pygsheets.authorize(service_file=self.credentials)\n', '  File "//anaconda/lib/python3.5/site-packages/pygsheets/client.py", line 515, in authorize\n    rclient = Client(oauth=credentials, **client_kwargs)\n', '  File "//anaconda/lib/python3.5/site-packages/pygsheets/client.py", line 72, in __init__\n    self._fetch_sheets()\n', '  File "//anaconda/lib/python3.5/site-packages/pygsheets/client.py", line 83, in _fetch_sheets\n    results = self._execute_request(None, request, False)\n', '  File "//anaconda/lib/python3.5/site-packages/pygsheets/client.py", line 381, in _execute_request\n    response = request.execute()\n', '  File "//anaconda/lib/python3.5/site-packages/oauth2client/_helpers.py", line 133, in positional_wrapper\n    return wrapped(*args, **kwargs)\n', '  File "//anaconda/lib/python3.5/site-packages/googleapiclient/http.py", line 835, in execute\n    method=str(self.method), body=self.body, headers=self.headers)\n', '  File "//anaconda/lib/python3.5/site-packages/googleapiclient/http.py", line 162, in _retry_request\n    resp, content = http.request(uri, method, *args, **kwargs)\n', '  File "//anaconda/lib/python3.5/site-packages/oauth2client/transport.py", line 159, in new_request\n    credentials._refresh(orig_request_method)\n', '  File "//anaconda/lib/python3.5/site-packages/oauth2client/client.py", line 749, in _refresh\n    self._do_refresh_request(http)\n', '  File "//anaconda/lib/python3.5/site-packages/oauth2client/client.py", line 774, in _do_refresh_request\n    body = self._generate_refresh_request_body()\n', '  File "//anaconda/lib/python3.5/site-packages/oauth2client/client.py", line 1484, in _generate_refresh_request_body\n    assertion = self._generate_assertion()\n', '  File "//anaconda/lib/python3.5/site-packages/oauth2client/service_account.py", line 385, in _generate_assertion\n    key_id=self._private_key_id)\n', '  File "//anaconda/lib/python3.5/site-packages/oauth2client/crypt.py", line 97, in make_signed_jwt\n    signature = signer.sign(signing_input)\n', '  File "//anaconda/lib/python3.5/site-packages/oauth2client/_openssl_crypt.py", line 97, in sign\n    return crypto.sign(self._key, message, \'sha256\')\n', '  File "//anaconda/lib/python3.5/site-packages/OpenSSL/crypto.py", line 2563, in sign\n    md_ctx = _ffi.new("EVP_MD_CTX*")\n']
2017-06-19 19:54:30,210 - ERROR - Exception HttpError: <HttpError 403 when requesting https://www.googleapis.com/drive/v3/files?alt=json&q=mimeType%3D%27application%2Fvnd.google-apps.spreadsheet%27&corpus=user&pageSize=500&fields=files%28id%2C+name%29 returned "Access Not Configured. Drive API has not been used in project 481977858493 before or it is disabled. Enable it by visiting https://console.developers.google.com/apis/api/drive.googleapis.com/overview?project=481977858493 then retry. If you enabled this API recently, wait a few minutes for the action to propagate to our systems and retry.">
	['  File "init_spreadsheet.py", line 18, in <module>\n    spread = SheetsDecorator(load_spreadsheet=False, credentials=credentials_path)\n', '  File "/Users/austinshih/Desktop/Chomppa/beer_pong_bot-master/chomps/sheetsdecorator.py", line 24, in __init__\n    self._init_pygsheets()\n', '  File "/Users/austinshih/Desktop/Chomppa/beer_pong_bot-master/chomps/sheetsdecorator.py", line 46, in _init_pygsheets\n    self.gc = pygsheets.authorize(service_file=self.credentials)\n', '  File "//anaconda/lib/python3.5/site-packages/pygsheets/client.py", line 515, in authorize\n    rclient = Client(oauth=credentials, **client_kwargs)\n', '  File "//anaconda/lib/python3.5/site-packages/pygsheets/client.py", line 72, in __init__\n    self._fetch_sheets()\n', '  File "//anaconda/lib/python3.5/site-packages/pygsheets/client.py", line 83, in _fetch_sheets\n    results = self._execute_request(None, request, False)\n', '  File "//anaconda/lib/python3.5/site-packages/pygsheets/client.py", line 381, in _execute_request\n    response = request.execute()\n', '  File "//anaconda/lib/python3.5/site-packages/oauth2client/_helpers.py", line 133, in positional_wrapper\n    return wrapped(*args, **kwargs)\n', '  File "//anaconda/lib/python3.5/site-packages/googleapiclient/http.py", line 840, in execute\n    raise HttpError(resp, content, uri=self.uri)\n']
2017-06-19 20:02:31,469 - ERROR - Exception ImportError: No module named 'BaseHTTPServer'
	['  File "run.py", line 7, in <module>\n    import chomps.chomps as chomps\n', '  File "/Users/austinshih/Desktop/Chomppa/beer_pong_bot-master/chomps/chomps.py", line 1, in <module>\n    from BaseHTTPServer import HTTPServer\n']
2017-06-19 20:04:19,889 - ERROR - Exception ImportError: No module named 'BaseHTTPServer'
	['  File "run.py", line 7, in <module>\n    import chomps.chomps as chomps\n', '  File "/Users/austinshih/Desktop/Chomppa/beer_pong_bot-master/chomps/chomps.py", line 1, in <module>\n    from BaseHTTPServer import HTTPServer\n']
2017-06-19 20:08:29,524 - ERROR - Exception ImportError: No module named 'BaseHTTPServer'
	['  File "run.py", line 7, in <module>\n    import chomps.chomps as chomps\n', '  File "/Users/austinshih/Desktop/Chomppa/beer_pong_bot-master/chomps/chomps.py", line 1, in <module>\n    from BaseHTTPServer import HTTPServer\n']
